Workbook

Sheet Final Table
A1: Zip Code | B1: County | C1: # of Baseball fields in the area | D1: Average of % LI (Y) Based on Free Lunches | E1: Average of Need % based on SVI | F1: Count of # of B&GC in ZIP | G1: Strong Infrastructure? | H1: Strong Org? | I1: RBI Readiness | J1: Note of Local Infrastructure
A2: 94621 | B2: Alameda County | C2: 11 | D2: 0.93574757 | E2: 0.6446441 | F2: 14 | G2: TRUE | H2: TRUE | I2: =(E2*0.5) + ((C2/MAX($C$2:$C$60))*0.25) + ((F2/MAX($F$2:$F$60))*0.25) -> 0.66954427 | J2: =_xlfn.IFNA(_xlfn.XLOOKUP(Table1[[#This Row],[Zip Code]],'Neighborhood Reviews'!$A$3:$A$14,'Neighborhood Reviews'!$E$3:$E$14),"") -> Yes
A3: 94603 | B3: Alameda County | C3: 2 | D3: 0.95419108 | E3: 0.53796242 | F3: 11 | G3: FALSE | H3: TRUE | I3: =(E3*0.5) + ((C3/MAX($C$2:$C$60))*0.25) + ((F3/MAX($F$2:$F$60))*0.25) -> 0.44953677 | J3: =_xlfn.IFNA(_xlfn.XLOOKUP(Table1[[#This Row],[Zip Code]],'Neighborhood Reviews'!$A$3:$A$14,'Neighborhood Reviews'!$E$3:$E$14),"") -> Yes
A4: 94601 | B4: Alameda County | C4: 1 | D4: 0.87118077 | E4: 0.46025929 | F4: 18 | G4: FALSE | H4: TRUE | I4: =(E4*0.5) + ((C4/MAX($C$2:$C$60))*0.25) + ((F4/MAX($F$2:$F$60))*0.25) -> 0.49401853 | J4: =_xlfn.IFNA(_xlfn.XLOOKUP(Table1[[#This Row],[Zip Code]],'Neighborhood Reviews'!$A$3:$A$14,'Neighborhood Reviews'!$E$3:$E$14),"") -> Weak - no mention in 221 reviews
A5: 94124 | B5: San Francisco County | C5: 9 | D5: 0.84252252 | E5: 0.43334494 | F5: 8 | G5: TRUE | H5: TRUE | I5: =(E5*0.5) + ((C5/MAX($C$2:$C$60))*0.25) + ((F5/MAX($F$2:$F$60))*0.25) -> 0.45278358 | J5: =_xlfn.IFNA(_xlfn.XLOOKUP(Table1[[#This Row],[Zip Code]],'Neighborhood Reviews'!$A$3:$A$14,'Neighborhood Reviews'!$E$3:$E$14),"")
A6: 94578 | B6: Alameda County | D6: 0.84558499 | E6: 0.31194379 | F6: 3 | G6: FALSE | H6: FALSE | I6: =(E6*0.5) + ((C6/MAX($C$2:$C$60))*0.25) + ((F6/MAX($F$2:$F$60))*0.25) -> 0.19763856 | J6: =_xlfn.IFNA(_xlfn.XLOOKUP(Table1[[#This Row],[Zip Code]],'Neighborhood Reviews'!$A$3:$A$14,'Neighborhood Reviews'!$E$3:$E$14),"")
A7: 94605 | B7: Alameda County | D7: 0.83040047 | E7: 0.30402077 | F7: 14 | G7: FALSE | H7: FALSE | I7: =(E7*0.5) + ((C7/MAX($C$2:$C$60))*0.25) + ((F7/MAX($F$2:$F$60))*0.25) -> 0.34645483 | J7: =_xlfn.IFNA(_xlfn.XLOOKUP(Table1[[#This Row],[Zip Code]],'Neighborhood Reviews'!$A$3:$A$14,'Neighborhood Reviews'!$E$3:$E$14),"") -> Partial - general sports fields confirmed
A8: 94706 | B8: Alameda County | D8: 0.32064781 | E8: 0.30172678 | F8: 5 | G8: FALSE | H8: FALSE | I8: =(E8*0.5) + ((C8/MAX($C$2:$C$60))*0.25) + ((F8/MAX($F$2:$F$60))*0.25) -> 0.22030783 | J8: =_xlfn.IFNA(_xlfn.XLOOKUP(Table1[[#This Row],[Zip Code]],'Neighborhood Reviews'!$A$3:$A$14,'Neighborhood Reviews'!$E$3:$E$14),"")
A9: 94544 | B9: Alameda County | D9: 0.76755765 | E9: 0.29877043 | F9: 8 | G9: FALSE | H9: FALSE | I9: =(E9*0.5) + ((C9/MAX($C$2:$C$60))*0.25) + ((F9/MAX($F$2:$F$60))*0.25) -> 0.26049633 | J9: =_xlfn.IFNA(_xlfn.XLOOKUP(Table1[[#This Row],[Zip Code]],'Neighborhood Reviews'!$A$3:$A$14,'Neighborhood Reviews'!$E$3:$E$14),"") -> Yes at Sorensdale (3 fields). Historical at Palma Ceia (diamond may no longer be active).
A10: 94541 | B10: Alameda County | C10: 2 | D10: 0.79248307 | E10: 0.29813296 | F10: 11 | G10: FALSE | H10: FALSE | I10: =(E10*0.5) + ((C10/MAX($C$2:$C$60))*0.25) + ((F10/MAX($F$2:$F$60))*0.25) -> 0.32962203 | J10: =_xlfn.IFNA(_xlfn.XLOOKUP(Table1[[#This Row],[Zip Code]],'Neighborhood Reviews'!$A$3:$A$14,'Neighborhood Reviews'!$E$3:$E$14),"") -> Yes - strong. Two diamonds at Centennial, softball at Bret Harte, baseball field with bleachers at Cannery.
A11: 94568 | B11: Alameda County | D11: 0.1492248 | E11: 0.28134823 | F11: 12 | G11: FALSE | H11: FALSE | I11: =(E11*0.5) + ((C11/MAX($C$2:$C$60))*0.25) + ((F11/MAX($F$2:$F$60))*0.25) -> 0.30734078 | J11: =_xlfn.IFNA(_xlfn.XLOOKUP(Table1[[#This Row],[Zip Code]],'Neighborhood Reviews'!$A$3:$A$14,'Neighborhood Reviews'!$E$3:$E$14),"")
A12: 94606 | B12: Alameda County | C12: 3 | D12: 0.86405346 | E12: 0.27677092 | F12: 7 | G12: FALSE | H12: FALSE | I12: =(E12*0.5) + ((C12/MAX($C$2:$C$60))*0.25) + ((F12/MAX($F$2:$F$60))*0.25) -> 0.27727435 | J12: =_xlfn.IFNA(_xlfn.XLOOKUP(Table1[[#This Row],[Zip Code]],'Neighborhood Reviews'!$A$3:$A$14,'Neighborhood Reviews'!$E$3:$E$14),"") -> Yes at Garfield - confirmed diamond. Absent at San Antonio.
A13: 94619 | B13: Alameda County | C13: 3 | D13: 0.63109996 | E13: 0.26992874 | F13: 8 | G13: FALSE | H13: FALSE | I13: =(E13*0.5) + ((C13/MAX($C$2:$C$60))*0.25) + ((F13/MAX($F$2:$F$60))*0.25) -> 0.28774215 | J13: =_xlfn.IFNA(_xlfn.XLOOKUP(Table1[[#This Row],[Zip Code]],'Neighborhood Reviews'!$A$3:$A$14,'Neighborhood Reviews'!$E$3:$E$14),"")
A14: 94501 | B14: Alameda County | C14: 12 | D14: 0.38888914 | E14: 0.26763912 | F14: 14 | G14: FALSE | H14: FALSE | I14: =(E14*0.5) + ((C14/MAX($C$2:$C$60))*0.25) + ((F14/MAX($F$2:$F$60))*0.25) -> 0.49493067 | J14: =_xlfn.IFNA(_xlfn.XLOOKUP(Table1[[#This Row],[Zip Code]],'Neighborhood Reviews'!$A$3:$A$14,'Neighborhood Reviews'!$E$3:$E$14),"")
A15: 94702 | B15: Alameda County | D15: 0.31935445 | E15: 0.26314276 | F15: 3 | G15: FALSE | H15: FALSE | I15: =(E15*0.5) + ((C15/MAX($C$2:$C$60))*0.25) + ((F15/MAX($F$2:$F$60))*0.25) -> 0.17323805 | J15: =_xlfn.IFNA(_xlfn.XLOOKUP(Table1[[#This Row],[Zip Code]],'Neighborhood Reviews'!$A$3:$A$14,'Neighborhood Reviews'!$E$3:$E$14),"")
A16: 94551 | B16: Alameda County | D16: 0.25651532 | E16: 0.24954455 | F16: 7 | G16: FALSE | H16: FALSE | I16: =(E16*0.5) + ((C16/MAX($C$2:$C$60))*0.25) + ((F16/MAX($F$2:$F$60))*0.25) -> 0.2219945 | J16: =_xlfn.IFNA(_xlfn.XLOOKUP(Table1[[#This Row],[Zip Code]],'Neighborhood Reviews'!$A$3:$A$14,'Neighborhood Reviews'!$E$3:$E$14),"")
A17: 94546 | B17: Alameda County | C17: 5 | D17: 0.39945784 | E17: 0.24872839 | F17: 9 | G17: FALSE | H17: FALSE | I17: =(E17*0.5) + ((C17/MAX($C$2:$C$60))*0.25) + ((F17/MAX($F$2:$F$60))*0.25) -> 0.31880864 | J17: =_xlfn.IFNA(_xlfn.XLOOKUP(Table1[[#This Row],[Zip Code]],'Neighborhood Reviews'!$A$3:$A$14,'Neighborhood Reviews'!$E$3:$E$14),"")
A18: 94588 | B18: Alameda County | D18: 0.094344217 | E18: 0.24761993 | F18: 6 | G18: FALSE | H18: FALSE | I18: =(E18*0.5) + ((C18/MAX($C$2:$C$60))*0.25) + ((F18/MAX($F$2:$F$60))*0.25) -> 0.2071433 | J18: =_xlfn.IFNA(_xlfn.XLOOKUP(Table1[[#This Row],[Zip Code]],'Neighborhood Reviews'!$A$3:$A$14,'Neighborhood Reviews'!$E$3:$E$14),"")
A19: 94566 | B19: Alameda County | D19: 0.10985022 | E19: 0.22247883 | F19: 8 | G19: FALSE | H19: FALSE | I19: =(E19*0.5) + ((C19/MAX($C$2:$C$60))*0.25) + ((F19/MAX($F$2:$F$60))*0.25) -> 0.22235052 | J19: =_xlfn.IFNA(_xlfn.XLOOKUP(Table1[[#This Row],[Zip Code]],'Neighborhood Reviews'!$A$3:$A$14,'Neighborhood Reviews'!$E$3:$E$14),"")
A20: 94577 | B20: Alameda County | C20: 7 | D20: 0.73903632 | E20: 0.22196599 | F20: 8 | G20: FALSE | H20: FALSE | I20: =(E20*0.5) + ((C20/MAX($C$2:$C$60))*0.25) + ((F20/MAX($F$2:$F$60))*0.25) -> 0.31931633 | J20: =_xlfn.IFNA(_xlfn.XLOOKUP(Table1[[#This Row],[Zip Code]],'Neighborhood Reviews'!$A$3:$A$14,'Neighborhood Reviews'!$E$3:$E$14),"")
A21: 94134 | B21: San Francisco County | C21: 16 | D21: 0.73463699 | E21: 0.22140514 | F21: 8 | G21: FALSE | H21: FALSE | I21: =(E21*0.5) + ((C21/MAX($C$2:$C$60))*0.25) + ((F21/MAX($F$2:$F$60))*0.25) -> 0.4440359 | J21: =_xlfn.IFNA(_xlfn.XLOOKUP(Table1[[#This Row],[Zip Code]],'Neighborhood Reviews'!$A$3:$A$14,'Neighborhood Reviews'!$E$3:$E$14),"")
A22: 94580 | B22: Alameda County | C22: 2 | D22: 0.7420905 | E22: 0.21822442 | F22: 10 | G22: FALSE | H22: FALSE | I22: =(E22*0.5) + ((C22/MAX($C$2:$C$60))*0.25) + ((F22/MAX($F$2:$F$60))*0.25) -> 0.27577888 | J22: =_xlfn.IFNA(_xlfn.XLOOKUP(Table1[[#This Row],[Zip Code]],'Neighborhood Reviews'!$A$3:$A$14,'Neighborhood Reviews'!$E$3:$E$14),"")
A23: 94545 | B23: Alameda County | D23: 0.68544797 | E23: 0.20173981 | F23: 9 | G23: FALSE | H23: FALSE | I23: =(E23*0.5) + ((C23/MAX($C$2:$C$60))*0.25) + ((F23/MAX($F$2:$F$60))*0.25) -> 0.2258699 | J23: =_xlfn.IFNA(_xlfn.XLOOKUP(Table1[[#This Row],[Zip Code]],'Neighborhood Reviews'!$A$3:$A$14,'Neighborhood Reviews'!$E$3:$E$14),"")
A24: 94112 | B24: San Francisco County | C24: 18 | D24: 0.62136984 | E24: 0.19910241 | F24: 10 | G24: FALSE | H24: FALSE | I24: =(E24*0.5) + ((C24/MAX($C$2:$C$60))*0.25) + ((F24/MAX($F$2:$F$60))*0.25) -> 0.4884401 | J24: =_xlfn.IFNA(_xlfn.XLOOKUP(Table1[[#This Row],[Zip Code]],'Neighborhood Reviews'!$A$3:$A$14,'Neighborhood Reviews'!$E$3:$E$14),"")
A25: 94602 | B25: Alameda County | C25: 5 | D25: 0.66635862 | E25: 0.19259218 | F25: 4 | G25: FALSE | H25: FALSE | I25: =(E25*0.5) + ((C25/MAX($C$2:$C$60))*0.25) + ((F25/MAX($F$2:$F$60))*0.25) -> 0.22129609 | J25: =_xlfn.IFNA(_xlfn.XLOOKUP(Table1[[#This Row],[Zip Code]],'Neighborhood Reviews'!$A$3:$A$14,'Neighborhood Reviews'!$E$3:$E$14),"")
A26: 94502 | B26: Alameda County | C26: 4 | D26: 0.20309896 | E26: 0.18578191 | F26: 2 | G26: FALSE | H26: FALSE | I26: =(E26*0.5) + ((C26/MAX($C$2:$C$60))*0.25) + ((F26/MAX($F$2:$F$60))*0.25) -> 0.17622429 | J26: =_xlfn.IFNA(_xlfn.XLOOKUP(Table1[[#This Row],[Zip Code]],'Neighborhood Reviews'!$A$3:$A$14,'Neighborhood Reviews'!$E$3:$E$14),"")
A27: 94587 | B27: Alameda County | C27: 4 | D27: 0.48843833 | E27: 0.1854275 | F27: 3 | G27: FALSE | H27: FALSE | I27: =(E27*0.5) + ((C27/MAX($C$2:$C$60))*0.25) + ((F27/MAX($F$2:$F$60))*0.25) -> 0.18993597 | J27: =_xlfn.IFNA(_xlfn.XLOOKUP(Table1[[#This Row],[Zip Code]],'Neighborhood Reviews'!$A$3:$A$14,'Neighborhood Reviews'!$E$3:$E$14),"") -> Yes - confirmed at all three. Town Estates has four baseball fields.
A28: 94550 | B28: Alameda County | D28: 0.16129073 | E28: 0.18527887 | F28: 9 | G28: FALSE | H28: FALSE | I28: =(E28*0.5) + ((C28/MAX($C$2:$C$60))*0.25) + ((F28/MAX($F$2:$F$60))*0.25) -> 0.21763943 | J28: =_xlfn.IFNA(_xlfn.XLOOKUP(Table1[[#This Row],[Zip Code]],'Neighborhood Reviews'!$A$3:$A$14,'Neighborhood Reviews'!$E$3:$E$14),"")
A29: 94121 | B29: San Francisco County | C29: 4 | D29: 0.40188064 | E29: 0.1851105 | F29: 5 | G29: FALSE | H29: FALSE | I29: =(E29*0.5) + ((C29/MAX($C$2:$C$60))*0.25) + ((F29/MAX($F$2:$F$60))*0.25) -> 0.21755525 | J29: =_xlfn.IFNA(_xlfn.XLOOKUP(Table1[[#This Row],[Zip Code]],'Neighborhood Reviews'!$A$3:$A$14,'Neighborhood Reviews'!$E$3:$E$14),"")
A30: 94710 | B30: Alameda County | C30: 5 | D30: 0.33842239 | E30: 0.17985319 | F30: 1 | G30: FALSE | H30: FALSE | I30: =(E30*0.5) + ((C30/MAX($C$2:$C$60))*0.25) + ((F30/MAX($F$2:$F$60))*0.25) -> 0.17325993 | J30: =_xlfn.IFNA(_xlfn.XLOOKUP(Table1[[#This Row],[Zip Code]],'Neighborhood Reviews'!$A$3:$A$14,'Neighborhood Reviews'!$E$3:$E$14),"")
A31: 94552 | B31: Alameda County | C31: 3 | D31: 0.31335596 | E31: 0.17836816 | F31: 4 | G31: FALSE | H31: FALSE | I31: =(E31*0.5) + ((C31/MAX($C$2:$C$60))*0.25) + ((F31/MAX($F$2:$F$60))*0.25) -> 0.1864063 | J31: =_xlfn.IFNA(_xlfn.XLOOKUP(Table1[[#This Row],[Zip Code]],'Neighborhood Reviews'!$A$3:$A$14,'Neighborhood Reviews'!$E$3:$E$14),"")
A32: 94108 | B32: San Francisco County | D32: 0.84299735 | E32: 0.17264316 | F32: 2 | G32: FALSE | H32: FALSE | I32: =(E32*0.5) + ((C32/MAX($C$2:$C$60))*0.25) + ((F32/MAX($F$2:$F$60))*0.25) -> 0.11409936 | J32: =_xlfn.IFNA(_xlfn.XLOOKUP(Table1[[#This Row],[Zip Code]],'Neighborhood Reviews'!$A$3:$A$14,'Neighborhood Reviews'!$E$3:$E$14),"")
A33: 94609 | B33: Alameda County | C33: 3 | D33: 0.60214082 | E33: 0.16955557 | F33: 3 | G33: FALSE | H33: FALSE | I33: =(E33*0.5) + ((C33/MAX($C$2:$C$60))*0.25) + ((F33/MAX($F$2:$F$60))*0.25) -> 0.16811112 | J33: =_xlfn.IFNA(_xlfn.XLOOKUP(Table1[[#This Row],[Zip Code]],'Neighborhood Reviews'!$A$3:$A$14,'Neighborhood Reviews'!$E$3:$E$14),"")
A34: 94133 | B34: San Francisco County | C34: 4 | D34: 0.59671352 | E34: 0.16696483 | F34: 6 | G34: FALSE | H34: FALSE | I34: =(E34*0.5) + ((C34/MAX($C$2:$C$60))*0.25) + ((F34/MAX($F$2:$F$60))*0.25) -> 0.2223713 | J34: =_xlfn.IFNA(_xlfn.XLOOKUP(Table1[[#This Row],[Zip Code]],'Neighborhood Reviews'!$A$3:$A$14,'Neighborhood Reviews'!$E$3:$E$14),"")
A35: 94110 | B35: San Francisco County | C35: 3 | D35: 0.72971339 | E35: 0.16587811 | F35: 9 | G35: FALSE | H35: FALSE | I35: =(E35*0.5) + ((C35/MAX($C$2:$C$60))*0.25) + ((F35/MAX($F$2:$F$60))*0.25) -> 0.24960572 | J35: =_xlfn.IFNA(_xlfn.XLOOKUP(Table1[[#This Row],[Zip Code]],'Neighborhood Reviews'!$A$3:$A$14,'Neighborhood Reviews'!$E$3:$E$14),"")
A36: 94703 | B36: Alameda County | C36: 4 | D36: 0.32053222 | E36: 0.16553412 | F36: 2 | G36: FALSE | H36: FALSE | I36: =(E36*0.5) + ((C36/MAX($C$2:$C$60))*0.25) + ((F36/MAX($F$2:$F$60))*0.25) -> 0.16610039 | J36: =_xlfn.IFNA(_xlfn.XLOOKUP(Table1[[#This Row],[Zip Code]],'Neighborhood Reviews'!$A$3:$A$14,'Neighborhood Reviews'!$E$3:$E$14),"")
A37: 94579 | B37: Alameda County | C37: 5 | D37: 0.71134914 | E37: 0.16531367 | F37: 4 | G37: FALSE | H37: FALSE | I37: =(E37*0.5) + ((C37/MAX($C$2:$C$60))*0.25) + ((F37/MAX($F$2:$F$60))*0.25) -> 0.20765683 | J37: =_xlfn.IFNA(_xlfn.XLOOKUP(Table1[[#This Row],[Zip Code]],'Neighborhood Reviews'!$A$3:$A$14,'Neighborhood Reviews'!$E$3:$E$14),"")
A38: 94542 | B38: Alameda County | C38: 2 | D38: 0.46080999 | E38: 0.16330328 | F38: 2 | G38: FALSE | H38: FALSE | I38: =(E38*0.5) + ((C38/MAX($C$2:$C$60))*0.25) + ((F38/MAX($F$2:$F$60))*0.25) -> 0.13720719 | J38: =_xlfn.IFNA(_xlfn.XLOOKUP(Table1[[#This Row],[Zip Code]],'Neighborhood Reviews'!$A$3:$A$14,'Neighborhood Reviews'!$E$3:$E$14),"")
A39: 94102 | B39: San Francisco County | C39: 2 | D39: 0.74113475 | E39: 0.16208202 | F39: 1 | G39: FALSE | H39: FALSE | I39: =(E39*0.5) + ((C39/MAX($C$2:$C$60))*0.25) + ((F39/MAX($F$2:$F$60))*0.25) -> 0.12270767 | J39: =_xlfn.IFNA(_xlfn.XLOOKUP(Table1[[#This Row],[Zip Code]],'Neighborhood Reviews'!$A$3:$A$14,'Neighborhood Reviews'!$E$3:$E$14),"")
A40: 94116 | B40: San Francisco County | C40: 5 | D40: 0.46366932 | E40: 0.16165447 | F40: 6 | G40: FALSE | H40: FALSE | I40: =(E40*0.5) + ((C40/MAX($C$2:$C$60))*0.25) + ((F40/MAX($F$2:$F$60))*0.25) -> 0.23360501 | J40: =_xlfn.IFNA(_xlfn.XLOOKUP(Table1[[#This Row],[Zip Code]],'Neighborhood Reviews'!$A$3:$A$14,'Neighborhood Reviews'!$E$3:$E$14),"")
...

Sheet Neighborhood Reviews
A1: Column1 | B1: Column2 | C1: Column3 | D1: Column4 | E1: Column5 | F1: Column6 | G1: Column7 | H1: Column8 | I1: Column9 | J1: Column10 | K1: Column11 | L1: Column12
A2: ZIP | B2: Neighborhood | C2: City | D2: Fields Checked | E2: Baseball Present | F2: Condition | G2: Youth Activity | H2: Org Signal | I2: Gap Verdict | J2: Map View | K2: Sample Quotes | L2: Notes
A3: 94603 | B3: Sobrante Park / Elmhurst / Coliseum | C3: Oakland | D3: Sobrante Park diamond; Ira Jinkins Community Center | E3: Yes | F3: Needs investment | G3: Present | H3: None | I3: Strong gap | J3: RBI Officials | K3: "The soccer and baseball fields appear to be in need of some maintenance." | "Park & Recreation grew up here and my kids as well. They truly look out for the kids and families in the community." | L3: Primary demo case. Diamond confirmed. Bathrooms permanently closed. Ira Jinkins rec center 0.8mi away as org anchor. No RBI affiliate within 4 miles.
A4: 94621 | B4: Hegenberger / Coliseum area | C4: Oakland | D4: McConnell Field; Rickey Henderson Field | E4: Yes | F4: Usable but unsafe environment | G4: Limited - adults loitering | H4: None for youth | I4: Gap with safety caveats | J4: RBI Officials | K4: "The fields are nice to play baseball/softball but the people who hang around the park make it not a welcoming environment." | "Don't bring your kids to this park unless you are there with a big group." | L4: Field infrastructure confirmed. Safety environment is a real barrier. Flag as infrastructure AND environment investment needed, not just equipment drop.
A5: 94605 | B5: Eastmont / Millsmont / Maxwell Park | C5: Oakland | D5: Arroyo Viejo Recreation Center | E5: Partial - general sports fields confirmed | F5: Inconsistent | G5: Present but contested by time of day | H5: None for baseball | I5: Strong gap | J5: RBI Officials | K5: "Arroyo is in the midst of its renaissance, plenty of kids in their after school and summer program." | "Dirty, trash filled, broken glass... packed with adults, no kids at all." | L5: High-need neighborhood. Rec center on site is a potential org anchor. Youth programs already running. Baseball just needs to be added to existing infrastructure.
A6: 94606 | B6: Garfield / San Antonio / Clinton / Fremont | C6: Oakland | D6: Garfield Park Baseball Field; San Antonio Park; San Antonio Recreation Center | E6: Yes at Garfield - confirmed diamond. Absent at San Antonio. | F6: Unknown at Garfield - no reviews. Good at San Antonio. | G6: Strong at San Antonio - zero baseball signal | H6: None | I6: Strong gap - strongest invisible field in dataset | J6: RBI Officials | K6: "Lots of people playing soccer, basketball and running boxing camps every day." (San Antonio - zero baseball) | Garfield Park Baseball Field: zero reviews, no hours, no org. | L6: Garfield Park is a confirmed baseball field with literally zero community footprint online. Nobody knows it is there. Exactly what FieldFinder is built to surface.
A7: 94601 | B7: Fruitvale / Jingletown / San Antonio | C7: Oakland | D7: Brookdale Park | E7: Weak - no mention in 221 reviews | F7: Clean and well maintained | G7: Strong - soccer and basketball dominant | H7: None for baseball | I7: Needs investigation | J7: RBI Officials | K7: "Really good park offering so much for the youth, make sure you stop by and meet the director." | "A park full of adventures, clean, safe, kid friendly." | L7: High youth density and need but baseball interest signal is weak. Soccer dominates Fruitvale. Confirm whether a diamond physically exists before flagging as a gap.
A8: 94607 | B8: West Oakland / Acorn / McClymonds | C8: Oakland | D8: Raimondi Park; Oakland Ballers; DeFremery Park; DeFremery Recreation Center | E8: Yes - strong | F8: Excellent at Raimondi. DeFremery well managed. | G8: Strong - pop warner football, baseball, community events | H8: Oakland Ballers confirmed at Raimondi. DeFremery has baseball field but no league named. | I8: Already served at Raimondi. Possible gap at DeFremery. | J8: Families (Raimondi) + RBI Officials (DeFremery) | K8: "Raimondi park is now home to the Ballers and the park has never looked or felt better." | "Nice clean and quiet, baseball field, basketball courts, swimming pool, tennis courts." (DeFremery) | L8: Raimondi is covered - families view. DeFremery has confirmed baseball field and is well managed but no league attached in reviews. Worth flagging DeFremery as a secondary gap target.
A9: 94541 | B9: Downtown Hayward / Ashland / Cherryland | C9: Hayward / Unincorporated Alameda County | D9: Centennial Park; Bret Harte Park; Cannery Park | E9: Yes - strong. Two diamonds at Centennial, softball at Bret Harte, baseball field with bleachers at Cannery. | F9: Generally good across all three | G9: Present and family-friendly | H9: None named in any review | I9: Strong gap | J9: RBI Officials | K9: "Great park for sports activities! This park has two baseball diamonds, basketball court, large grass area." | "Very clean park with a baseball field with bleachers, restrooms available." | "Softball at its best." | L9: Multiple confirmed baseball diamonds, active family use, zero org presence. High Latino and Black population. Infrastructure is ready to use immediately. Strong deployment candidate.
A10: 94544 | B10: South Hayward | C10: Hayward | D10: Sorensdale Park; Ruus Park; Palma Ceia Park | E10: Yes at Sorensdale (3 fields). Historical at Palma Ceia (diamond may no longer be active). | F10: Good at Sorensdale. Basic but clean at Ruus. Palma Ceia maintenance could improve. | G10: Active at Sorensdale - son plays baseball there specifically mentioned | H10: Possible at Sorensdale - snack bar and game days suggest org presence | I10: Needs investigation at Sorensdale. Gap at Palma Ceia. | J10: RBI Officials (pending investigation) | K10: "Three baseball and softball fields for youth games. If you like baseball this is the place to be." | "My son plays baseball here." | "I miss the baseball park that was there once back in the day." (Palma Ceia) | L10: Sorensdale may already have an org - confirm before flagging as gap. Palma Ceia lost its baseball field and could be a restoration target paired with an RBI program.
A11: 94587 | B11: Union City / Alvarado | C11: Union City | D11: Town Estates Park; Contempo Park; Veterans Park | E11: Yes - confirmed at all three. Town Estates has four baseball fields. | F11: Good across the board. Town Estates and Veterans recently maintained. | G11: Strong - families actively playing baseball at Town Estates | H11: Unclear - four fields at Town Estates suggests possible org but no name mentioned | I11: Needs investigation | J11: RBI Officials (pending investigation) | K11: "Playing baseball in the baseball field, play soccer or kickball in the large grass area." | "Perfect park for families. Four baseball fields, playground for kids, picnic tables with grills." | "They saw a baseball game swing two balls out to neighboring cars." (Contempo - active play confirmed) | L11: Strong infrastructure and active use. Org status unclear at Town Estates - four fields suggests possible league. Moderate need with large Latino community. Confirm org before deployment decision.
A12: 94577 / 94578 / 94579 | B12: North / East / South San Leandro | C12: San Leandro | D12: San Leandro Ball Park; Stenzel Park; Bonaire Park | E12: Yes - strong at all three | F12: Good. San Leandro Ball Park has lights for night games. | G12: Active and organized - son plays baseball at Stenzel specifically mentioned | H12: San Leandro Little League (SLLL) confirmed active at San Leandro Ball Park and Stenzel | I12: Already served | J12: Families | K12: "SLLL has both spring and fall baseball at this park." | "When I was a kid I used to play little league here. My grandson still plays here." | "My son plays baseball here. A really nice park." | L12: San Leandro Little League is confirmed and active. These fields go in the families view as existing programs. Bonaire Park org status less certain - quick check recommended.
... A14: 94538 | B14: Irvington / Central Fremont | C14: Fremont | D14: Central Park Sports Complex | E14: Softball confirmed - baseball unclear | F14: Good | G14: Present | H14: None named | I14: Lower priority | J14: Neither | K14: "Great vibe for watching softball at night." | "Huge space and plenty of greenery. Many fields for sports." | L14: Moderate need area. Softball present but baseball signal weak. Not a priority compared to Oakland and Hayward zips.
